{
  "comments": [
    {
      "unresolved": false,
      "key": {
        "uuid": "5babc6c9_f3fcf468",
        "filename": "/PATCHSET_LEVEL",
        "patchSetId": 2
      },
      "lineNbr": 0,
      "author": {
        "id": 1003224
      },
      "writtenOn": "2023-09-07T20:40:40Z",
      "side": 1,
      "message": "(i defer to cferris/danalbert for python reviews...)",
      "revId": "85f6bd8ed5a6d8d35ed81df2bd796e93cdc2d171",
      "serverId": "85c56323-6fa9-3386-8a01-6480fb634889"
    },
    {
      "unresolved": false,
      "key": {
        "uuid": "588a6068_8af37414",
        "filename": "/PATCHSET_LEVEL",
        "patchSetId": 2
      },
      "lineNbr": 0,
      "author": {
        "id": 1905021
      },
      "writtenOn": "2023-09-08T00:58:07Z",
      "side": 1,
      "message": "Retested again, my bad,\n\nIf I use python3.6\n\n```\nTraceback (most recent call last):\n  File \"./development/scripts/acov-llvm.py\", line 70, in \u003cmodule\u003e\n    / _get_clang_revision()\n  File \"./development/scripts/acov-llvm.py\", line 65, in _get_clang_revision\n    text\u003dTrue)\n  File \"/usr/lib/python3.6/subprocess.py\", line 356, in check_output\n    **kwargs).stdout\n  File \"/usr/lib/python3.6/subprocess.py\", line 423, in run\n    with Popen(*popenargs, **kwargs) as process:\nTypeError: __init__() got an unexpected keyword argument \u0027text\u0027\n```\n\nIf I use python3.8, no issue, execpt that the final covreport folder can\u0027t be access from samba.\n\nSo updated the change to correct the permission only.",
      "revId": "85f6bd8ed5a6d8d35ed81df2bd796e93cdc2d171",
      "serverId": "85c56323-6fa9-3386-8a01-6480fb634889"
    },
    {
      "unresolved": true,
      "key": {
        "uuid": "922644a5_1b2b851a",
        "filename": "scripts/acov-llvm.py",
        "patchSetId": 2
      },
      "lineNbr": 196,
      "author": {
        "id": 1003224
      },
      "writtenOn": "2023-09-07T20:40:40Z",
      "side": 1,
      "message": "this seems unrelated?",
      "revId": "85f6bd8ed5a6d8d35ed81df2bd796e93cdc2d171",
      "serverId": "85c56323-6fa9-3386-8a01-6480fb634889"
    },
    {
      "unresolved": true,
      "key": {
        "uuid": "6d76b098_19dd0e9b",
        "filename": "scripts/acov-llvm.py",
        "patchSetId": 2
      },
      "lineNbr": 196,
      "author": {
        "id": 1043845
      },
      "writtenOn": "2023-09-07T20:42:18Z",
      "side": 1,
      "message": "All of this seems unrelated. Which part of this fixing Python 3.8? What\u0027s the bug?",
      "parentUuid": "922644a5_1b2b851a",
      "revId": "85f6bd8ed5a6d8d35ed81df2bd796e93cdc2d171",
      "serverId": "85c56323-6fa9-3386-8a01-6480fb634889"
    }
  ]
}